I'm sorry, but an uncaught exception occurred.

While running game code:
  File "game/scene2.rpy", line 36, in script
    scene mov_back fadein 1.0
Exception: Image 'mov_back' does not accept attributes 'fadein 1 .0'.

-- Full Traceback ------------------------------------------------------------

Full traceback:
  File "game/scene2.rpy", line 36, in script
    scene mov_back fadein 1.0
  File "C:\Users\Michelle\Desktop\renpy-8.3.0-sdk\renpy\ast.py", line 1245, in execute
    show_imspec(self.imspec, atl=getattr(self, "atl", None))
  File "C:\Users\Michelle\Desktop\renpy-8.3.0-sdk\renpy\ast.py", line 1074, in show_imspec
    renpy.config.show(name,
  File "C:\Users\Michelle\Desktop\renpy-8.3.0-sdk\renpy\exports\displayexports.py", line 477, in show
    if not base.find_target() and renpy.config.missing_show:
  File "C:\Users\Michelle\Desktop\renpy-8.3.0-sdk\renpy\display\image.py", line 421, in find_target
    self.target = target._duplicate(a)
  File "C:\Users\Michelle\Desktop\renpy-8.3.0-sdk\renpy\display\displayable.py", line 249, in _duplicate
    args.extraneous()
  File "C:\Users\Michelle\Desktop\renpy-8.3.0-sdk\renpy\display\displayable.py", line 109, in extraneous
    raise Exception("Image '{}' does not accept attributes '{}'.".format(
Exception: Image 'mov_back' does not accept attributes 'fadein 1 .0'.

Windows-10-10.0.22631 AMD64
Ren'Py 8.3.0.24082114
20is20 1.0
Sun Sep 29 02:07:25 2024
